Traceback (most recent call last):
  File "C:\Users\juacevedo.ATLANTICQI\AppData\Local\miniconda3\envs\ml_venv\lib\site-packages\nbclient\client.py", line 778, in _async_poll_for_reply
    msg = await ensure_async(self.kc.shell_channel.get_msg(timeout=new_timeout))
  File "C:\Users\juacevedo.ATLANTICQI\AppData\Local\miniconda3\envs\ml_venv\lib\site-packages\jupyter_core\utils\__init__.py", line 182, in ensure_async
    result = await obj
  File "C:\Users\juacevedo.ATLANTICQI\AppData\Local\miniconda3\envs\ml_venv\lib\site-packages\jupyter_client\channels.py", line 315, in get_msg
    raise Empty
_queue.Empty

During handling of the above exception, another exception occurred:

Traceback (most recent call last):
  File "C:\Users\juacevedo.ATLANTICQI\AppData\Local\miniconda3\envs\ml_venv\lib\site-packages\jupyter_cache\executors\utils.py", line 58, in single_nb_execution
    executenb(
  File "C:\Users\juacevedo.ATLANTICQI\AppData\Local\miniconda3\envs\ml_venv\lib\site-packages\nbclient\client.py", line 1305, in execute
    return NotebookClient(nb=nb, resources=resources, km=km, **kwargs).execute()
  File "C:\Users\juacevedo.ATLANTICQI\AppData\Local\miniconda3\envs\ml_venv\lib\site-packages\jupyter_core\utils\__init__.py", line 166, in wrapped
    return loop.run_until_complete(inner)
  File "C:\Users\juacevedo.ATLANTICQI\AppData\Local\miniconda3\envs\ml_venv\lib\asyncio\base_events.py", line 647, in run_until_complete
    return future.result()
  File "C:\Users\juacevedo.ATLANTICQI\AppData\Local\miniconda3\envs\ml_venv\lib\site-packages\nbclient\client.py", line 705, in async_execute
    await self.async_execute_cell(
  File "C:\Users\juacevedo.ATLANTICQI\AppData\Local\miniconda3\envs\ml_venv\lib\site-packages\nbclient\client.py", line 1001, in async_execute_cell
    exec_reply = await self.task_poll_for_reply
  File "C:\Users\juacevedo.ATLANTICQI\AppData\Local\miniconda3\envs\ml_venv\lib\site-packages\nbclient\client.py", line 802, in _async_poll_for_reply
    error_on_timeout_execute_reply = await self._async_handle_timeout(timeout, cell)
  File "C:\Users\juacevedo.ATLANTICQI\AppData\Local\miniconda3\envs\ml_venv\lib\site-packages\nbclient\client.py", line 852, in _async_handle_timeout
    raise CellTimeoutError.error_from_timeout_and_cell(
nbclient.exceptions.CellTimeoutError: A cell timed out while it was being executed, after 30 seconds.
The message was: Cell execution timed out.
Here is a preview of the cell contents:
-------------------
['n_BTC = len(BTC_df) #Número total de cierres', 'n_test_req = [7,14,21,28] # Tamaño de conjunto de prueba', '', 'for n_test in n_test_req:', '    train_size = n_BTC - n_test # define el set de entrenamiento como el numero total de cierres menos el test.']
...
['    plt.figure(figsize = (12,8))', '    fig, ax = plt.subplots()', '    ax = train.loc[1:].plot(ax=ax)', '    plot_predict(model_fit, 1, ax=ax)', '    plt.show();']
-------------------

